[2024-06-03T14:22:21.291-0500] {local_task_job_runner.py:120} INFO - ::group::Pre task execution logs
[2024-06-03T14:22:21.376-0500] {taskinstance.py:2076} INFO - Dependencies all met for dep_context=non-requeueable deps ti=<TaskInstance: python_pipeline.clean_data manual__2024-06-03T19:22:15.369279+00:00 [queued]>
[2024-06-03T14:22:21.382-0500] {taskinstance.py:2076} INFO - Dependencies all met for dep_context=requeueable deps ti=<TaskInstance: python_pipeline.clean_data manual__2024-06-03T19:22:15.369279+00:00 [queued]>
[2024-06-03T14:22:21.383-0500] {taskinstance.py:2306} INFO - Starting attempt 1 of 1
[2024-06-03T14:22:21.402-0500] {taskinstance.py:2330} INFO - Executing <Task(PythonOperator): clean_data> on 2024-06-03 19:22:15.369279+00:00
[2024-06-03T14:22:21.406-0500] {standard_task_runner.py:63} INFO - Started process 12493 to run task
[2024-06-03T14:22:21.409-0500] {standard_task_runner.py:90} INFO - Running: ['airflow', 'tasks', 'run', 'python_pipeline', 'clean_data', 'manual__2024-06-03T19:22:15.369279+00:00', '--job-id', '38', '--raw', '--subdir', 'DAGS_FOLDER/data_cleaning.py', '--cfg-path', '/tmp/tmp9mhewp9h']
[2024-06-03T14:22:21.410-0500] {standard_task_runner.py:91} INFO - Job 38: Subtask clean_data
[2024-06-03T14:22:21.447-0500] {task_command.py:426} INFO - Running <TaskInstance: python_pipeline.clean_data manual__2024-06-03T19:22:15.369279+00:00 [running]> on host diallo
[2024-06-03T14:22:21.522-0500] {taskinstance.py:2648} INFO - Exporting env vars: AIRFLOW_CTX_DAG_OWNER='Diallo' AIRFLOW_CTX_DAG_ID='python_pipeline' AIRFLOW_CTX_TASK_ID='clean_data' AIRFLOW_CTX_EXECUTION_DATE='2024-06-03T19:22:15.369279+00:00' AIRFLOW_CTX_TRY_NUMBER='1' AIRFLOW_CTX_DAG_RUN_ID='manual__2024-06-03T19:22:15.369279+00:00'
[2024-06-03T14:22:21.523-0500] {taskinstance.py:430} INFO - ::endgroup::
[2024-06-03T14:22:21.541-0500] {taskinstance.py:441} INFO - ::group::Post task execution logs
[2024-06-03T14:22:21.542-0500] {taskinstance.py:2905} ERROR - Task failed with exception
Traceback (most recent call last):
  File "/home/diallo/Documents/workspace/Python/AirFlowProjects/AirFlow01/venv/lib/python3.10/site-packages/airflow/models/taskinstance.py", line 465, in _execute_task
    result = _execute_callable(context=context, **execute_callable_kwargs)
  File "/home/diallo/Documents/workspace/Python/AirFlowProjects/AirFlow01/venv/lib/python3.10/site-packages/airflow/models/taskinstance.py", line 432, in _execute_callable
    return execute_callable(context=context, **execute_callable_kwargs)
  File "/home/diallo/Documents/workspace/Python/AirFlowProjects/AirFlow01/venv/lib/python3.10/site-packages/airflow/models/baseoperator.py", line 400, in wrapper
    return func(self, *args, **kwargs)
  File "/home/diallo/Documents/workspace/Python/AirFlowProjects/AirFlow01/venv/lib/python3.10/site-packages/airflow/operators/python.py", line 235, in execute
    return_value = self.execute_callable()
  File "/home/diallo/Documents/workspace/Python/AirFlowProjects/AirFlow01/venv/lib/python3.10/site-packages/airflow/operators/python.py", line 252, in execute_callable
    return self.python_callable(*self.op_args, **self.op_kwargs)
  File "/home/diallo/airflow/dags/data_cleaning.py", line 33, in clean_data
    print(json_data.shape)
AttributeError: 'str' object has no attribute 'shape'
[2024-06-03T14:22:21.545-0500] {taskinstance.py:1206} INFO - Marking task as FAILED. dag_id=python_pipeline, task_id=clean_data, run_id=manual__2024-06-03T19:22:15.369279+00:00, execution_date=20240603T192215, start_date=20240603T192221, end_date=20240603T192221
[2024-06-03T14:22:21.561-0500] {standard_task_runner.py:110} ERROR - Failed to execute job 38 for task clean_data ('str' object has no attribute 'shape'; 12493)
[2024-06-03T14:22:21.581-0500] {local_task_job_runner.py:240} INFO - Task exited with return code 1
[2024-06-03T14:22:21.594-0500] {taskinstance.py:3498} INFO - 0 downstream tasks scheduled from follow-on schedule check
[2024-06-03T14:22:21.595-0500] {local_task_job_runner.py:222} INFO - ::endgroup::
