[2024-05-31T15:32:47.724-0500] {local_task_job_runner.py:120} INFO - ::group::Pre task execution logs
[2024-05-31T15:32:47.743-0500] {taskinstance.py:2076} INFO - Dependencies all met for dep_context=non-requeueable deps ti=<TaskInstance: python_operators_with_param.taskA_Hello manual__2024-05-31T20:32:45.332004+00:00 [queued]>
[2024-05-31T15:32:47.749-0500] {taskinstance.py:2076} INFO - Dependencies all met for dep_context=requeueable deps ti=<TaskInstance: python_operators_with_param.taskA_Hello manual__2024-05-31T20:32:45.332004+00:00 [queued]>
[2024-05-31T15:32:47.749-0500] {taskinstance.py:2306} INFO - Starting attempt 1 of 1
[2024-05-31T15:32:47.766-0500] {taskinstance.py:2330} INFO - Executing <Task(PythonOperator): taskA_Hello> on 2024-05-31 20:32:45.332004+00:00
[2024-05-31T15:32:47.768-0500] {standard_task_runner.py:63} INFO - Started process 13811 to run task
[2024-05-31T15:32:47.771-0500] {standard_task_runner.py:90} INFO - Running: ['airflow', 'tasks', 'run', 'python_operators_with_param', 'taskA_Hello', 'manual__2024-05-31T20:32:45.332004+00:00', '--job-id', '13', '--raw', '--subdir', 'DAGS_FOLDER/execute_with_params.py', '--cfg-path', '/tmp/tmp0e61u_1c']
[2024-05-31T15:32:47.773-0500] {standard_task_runner.py:91} INFO - Job 13: Subtask taskA_Hello
[2024-05-31T15:32:47.806-0500] {task_command.py:426} INFO - Running <TaskInstance: python_operators_with_param.taskA_Hello manual__2024-05-31T20:32:45.332004+00:00 [running]> on host diallo
[2024-05-31T15:32:47.872-0500] {taskinstance.py:2648} INFO - Exporting env vars: AIRFLOW_CTX_DAG_OWNER='Diallo' AIRFLOW_CTX_DAG_ID='python_operators_with_param' AIRFLOW_CTX_TASK_ID='taskA_Hello' AIRFLOW_CTX_EXECUTION_DATE='2024-05-31T20:32:45.332004+00:00' AIRFLOW_CTX_TRY_NUMBER='1' AIRFLOW_CTX_DAG_RUN_ID='manual__2024-05-31T20:32:45.332004+00:00'
[2024-05-31T15:32:47.873-0500] {taskinstance.py:430} INFO - ::endgroup::
[2024-05-31T15:32:47.884-0500] {taskinstance.py:441} INFO - ::group::Post task execution logs
[2024-05-31T15:32:47.884-0500] {taskinstance.py:2905} ERROR - Task failed with exception
Traceback (most recent call last):
  File "/home/diallo/Documents/workspace/Python/AirFlowProjects/AirFlow01/venv/lib/python3.10/site-packages/airflow/models/taskinstance.py", line 465, in _execute_task
    result = _execute_callable(context=context, **execute_callable_kwargs)
  File "/home/diallo/Documents/workspace/Python/AirFlowProjects/AirFlow01/venv/lib/python3.10/site-packages/airflow/models/taskinstance.py", line 432, in _execute_callable
    return execute_callable(context=context, **execute_callable_kwargs)
  File "/home/diallo/Documents/workspace/Python/AirFlowProjects/AirFlow01/venv/lib/python3.10/site-packages/airflow/models/baseoperator.py", line 400, in wrapper
    return func(self, *args, **kwargs)
  File "/home/diallo/Documents/workspace/Python/AirFlowProjects/AirFlow01/venv/lib/python3.10/site-packages/airflow/operators/python.py", line 235, in execute
    return_value = self.execute_callable()
  File "/home/diallo/Documents/workspace/Python/AirFlowProjects/AirFlow01/venv/lib/python3.10/site-packages/airflow/operators/python.py", line 252, in execute_callable
    return self.python_callable(*self.op_args, **self.op_kwargs)
  File "/home/diallo/airflow/dags/execute_with_params.py", line 15, in say_hello
    print("hello {name}".format(name))
KeyError: 'name'
[2024-05-31T15:32:47.888-0500] {taskinstance.py:1206} INFO - Marking task as FAILED. dag_id=python_operators_with_param, task_id=taskA_Hello, run_id=manual__2024-05-31T20:32:45.332004+00:00, execution_date=20240531T203245, start_date=20240531T203247, end_date=20240531T203247
[2024-05-31T15:32:47.901-0500] {standard_task_runner.py:110} ERROR - Failed to execute job 13 for task taskA_Hello ('name'; 13811)
[2024-05-31T15:32:47.943-0500] {local_task_job_runner.py:240} INFO - Task exited with return code 1
[2024-05-31T15:32:47.968-0500] {taskinstance.py:3498} INFO - 0 downstream tasks scheduled from follow-on schedule check
[2024-05-31T15:32:47.981-0500] {local_task_job_runner.py:222} INFO - ::endgroup::
